{"name": "test_success_search_02", "status": "skipped", "statusDetails": {"message": "AssertionError: code与预期不一致\nassert 401 == 0", "trace": "self = <pytest_autotest.Testcase.cases.test_userinfo.TestUser object at 0x10324d880>\n\n    @allure.step\n    @pytest.mark.xfail(condition=lambda: True, reason='this test is expecting failure')\n    def test_success_search_02(self):\n        t = tools.Yaml().case_detail('SearchUserMobile.yaml', 'search_user_mobile_02')\n        print(t)\n        host = self.config.get_config('测试环境').get('host')\n        url = t.get('url')\n        headers = t.get('headers')\n        method = t.get('method')\n        data = t.get('data')\n        expect = t.get('expected')\n    \n        if method == 'GET':\n            response = self.request.request_get(url=host+url, data=data, headers=headers).json()\n>           assert response['code'] == expect['code'], 'code与预期不一致'\nE           AssertionError: code与预期不一致\nE           assert 401 == 0\n\nTestcase/cases/test_userinfo.py:41: AssertionError"}, "steps": [{"name": "test_success_search_02", "status": "failed", "statusDetails": {"message": "AssertionError: code与预期不一致\nassert 401 == 0\n", "trace": "  File \"/Users/yanziqiang/PycharmProjects/PyEnv/env_pytest/lib/python3.9/site-packages/allure_commons/_allure.py\", line 157, in impl\n    return func(*a, **kw)\n  File \"/Users/yanziqiang/PycharmProjects/PyEnv/env_pytest/Autotest/pytest_autotest/Testcase/cases/test_userinfo.py\", line 41, in test_success_search_02\n    assert response['code'] == expect['code'], 'code与预期不一致'\n"}, "start": 1618383985841, "stop": 1618383985946}], "attachments": [{"name": "stdout", "source": "1b099d7b-cda1-4d7b-9249-27102beccb51-attachment.txt", "type": "text/plain"}], "start": 1618383985841, "stop": 1618383985946, "uuid": "c15d5a47-04dd-4928-bd7f-8361791bc4df", "historyId": "0e01cddbbe5bb31c5c58074d05b562d1", "testCaseId": "e542763dfcf9f1b1b85bb3d0eeefbd41", "fullName": "Testcase.cases.test_userinfo.TestUser#test_success_search_02", "labels": [{"name": "tag", "value": "@pytest.mark.xfail(condition=<function TestUser.<lambda> at 0x10324e4c0>, reason='this test is expecting failure')"}, {"name": "parentSuite", "value": "Testcase.cases"}, {"name": "suite", "value": "test_userinfo"}, {"name": "subSuite", "value": "TestUser"}, {"name": "host", "value": "yanziqiangdeMacBook-Pro.local"}, {"name": "thread", "value": "64738-MainThread"}, {"name": "framework", "value": "pytest"}, {"name": "language", "value": "cpython3"}, {"name": "package", "value": "Testcase.cases.test_userinfo"}]}